{
  "context": "Critical failure during refinement iteration 0. Stopping investigation.",
  "datetime": "2025-03-30T09:19:30.332421",
  "stack_trace": "Traceback (most recent call last):\n  File \"/home/phi/PROJECTS/geometor/seer/src/geometor/seer/seer.py\", line 163, in _investigate\n    # Call refine, which now also handles exceptions from its _generate calls\n                ^^^^^^^^^^^^^^^^^^^^^^^^^^^^^^^^^^^^^^^^^^^^^^^^^^^^^^^^^^^^^\n    ...<6 lines>...\n        current_iteration,\n    \n  File \"/home/phi/PROJECTS/geometor/seer/src/geometor/seer/seer.py\", line 371, in refine\n    # will handle history update based on this returned step.\n  File \"/home/phi/PROJECTS/geometor/seer/src/geometor/seer/seer.py\", line 341, in refine\n    try:\n    \n    ...<7 lines>...\n        task_step = self._generate(\n        ^\n  File \"/home/phi/PROJECTS/geometor/seer/src/geometor/seer/seer.py\", line 300, in _generate\n    task_step.log_response(response, response_time, retries=task_step.attempts)\n    ^^^^^\nException: ERROR: Failed to get a valid response after 2 attempts.\n",
  "exception": "ERROR: Failed to get a valid response after 2 attempts."
}