
ERROR

Critical failure during refinement iteration 0. Stopping investigation.
ERROR: Failed to get a valid response after 2 attempts.
Traceback (most recent call last):
  File "/home/phi/PROJECTS/geometor/seer/src/geometor/seer/seer.py", line 163, in _investigate
    # Call refine, which now also handles exceptions from its _generate calls
                ^^^^^^^^^^^^^^^^^^^^^^^^^^^^^^^^^^^^^^^^^^^^^^^^^^^^^^^^^^^^^
    ...<6 lines>...
        current_iteration,
    
  File "/home/phi/PROJECTS/geometor/seer/src/geometor/seer/seer.py", line 371, in refine
    # will handle history update based on this returned step.
  File "/home/phi/PROJECTS/geometor/seer/src/geometor/seer/seer.py", line 341, in refine
    try:
    
    ...<7 lines>...
        task_step = self._generate(
        ^
  File "/home/phi/PROJECTS/geometor/seer/src/geometor/seer/seer.py", line 300, in _generate
    task_step.log_response(response, response_time, retries=task_step.attempts)
    ^^^^^
Exception: ERROR: Failed to get a valid response after 2 attempts.

