
ERROR


Timeout of 120.0s exceeded, last exception: 429 You exceeded your current quota, please check your plan and billing details. For more information on this error, head to: https://ai.google.dev/gemini-api/docs/rate-limits. [violations {
}
, links {
  description: "Learn more about Gemini API quotas"
  url: "https://ai.google.dev/gemini-api/docs/rate-limits"
}
, retry_delay {
  seconds: 19
}
]
Traceback (most recent call last):
  File "/home/phi/.pyenv/versions/3.10.15/lib/python3.10/site-packages/google/api_core/grpc_helpers.py", line 76, in error_remapped_callable
    return callable_(*args, **kwargs)
  File "/home/phi/.pyenv/versions/3.10.15/lib/python3.10/site-packages/grpc/_channel.py", line 1181, in __call__
    return _end_unary_response_blocking(state, call, False, None)
  File "/home/phi/.pyenv/versions/3.10.15/lib/python3.10/site-packages/grpc/_channel.py", line 1006, in _end_unary_response_blocking
    raise _InactiveRpcError(state)  # pytype: disable=not-instantiable
grpc._channel._InactiveRpcError: <_InactiveRpcError of RPC that terminated with:
	status = StatusCode.RESOURCE_EXHAUSTED
	details = "You exceeded your current quota, please check your plan and billing details. For more information on this error, head to: https://ai.google.dev/gemini-api/docs/rate-limits."
	debug_error_string = "UNKNOWN:Error received from peer ipv4:108.177.98.95:443 {grpc_message:"You exceeded your current quota, please check your plan and billing details. For more information on this error, head to: https://ai.google.dev/gemini-api/docs/rate-limits.", grpc_status:8, created_time:"2025-03-24T16:43:40.464429795-07:00"}"
>

The above exception was the direct cause of the following exception:

Traceback (most recent call last):
  File "/home/phi/.pyenv/versions/3.10.15/lib/python3.10/site-packages/google/api_core/retry/retry_unary.py", line 144, in retry_target
    result = target()
  File "/home/phi/.pyenv/versions/3.10.15/lib/python3.10/site-packages/google/api_core/timeout.py", line 120, in func_with_timeout
    return func(*args, **kwargs)
  File "/home/phi/.pyenv/versions/3.10.15/lib/python3.10/site-packages/google/api_core/grpc_helpers.py", line 78, in error_remapped_callable
    raise exceptions.from_grpc_error(exc) from exc
google.api_core.exceptions.ResourceExhausted: 429 You exceeded your current quota, please check your plan and billing details. For more information on this error, head to: https://ai.google.dev/gemini-api/docs/rate-limits. [violations {
}
, links {
  description: "Learn more about Gemini API quotas"
  url: "https://ai.google.dev/gemini-api/docs/rate-limits"
}
, retry_delay {
  seconds: 19
}
]

The above exception was the direct cause of the following exception:

Traceback (most recent call last):
  File "/home/phi/PROJECTS/geometor/seer/src/geometor/seer/seer.py", line 54, in solve
    self._investigate(task, session_task)
  File "/home/phi/PROJECTS/geometor/seer/src/geometor/seer/seer.py", line 137, in _investigate
    task_step = self.refine(
  File "/home/phi/PROJECTS/geometor/seer/src/geometor/seer/seer.py", line 231, in refine
    task_step = self._generate(
  File "/home/phi/PROJECTS/geometor/seer/src/geometor/seer/seer.py", line 174, in _generate
    response = client.generate_content(total_prompt, tools=tools)
  File "/home/phi/PROJECTS/geometor/seer/src/geometor/seer/gemini_client.py", line 49, in generate_content
    raise e
  File "/home/phi/PROJECTS/geometor/seer/src/geometor/seer/gemini_client.py", line 40, in generate_content
    response = self.model.generate_content(
  File "/home/phi/.pyenv/versions/3.10.15/lib/python3.10/site-packages/google/generativeai/generative_models.py", line 331, in generate_content
    response = self._client.generate_content(
  File "/home/phi/.pyenv/versions/3.10.15/lib/python3.10/site-packages/google/ai/generativelanguage_v1beta/services/generative_service/client.py", line 830, in generate_content
    response = rpc(
  File "/home/phi/.pyenv/versions/3.10.15/lib/python3.10/site-packages/google/api_core/gapic_v1/method.py", line 131, in __call__
    return wrapped_func(*args, **kwargs)
  File "/home/phi/.pyenv/versions/3.10.15/lib/python3.10/site-packages/google/api_core/retry/retry_unary.py", line 293, in retry_wrapped_func
    return retry_target(
  File "/home/phi/.pyenv/versions/3.10.15/lib/python3.10/site-packages/google/api_core/retry/retry_unary.py", line 153, in retry_target
    _retry_error_helper(
  File "/home/phi/.pyenv/versions/3.10.15/lib/python3.10/site-packages/google/api_core/retry/retry_base.py", line 221, in _retry_error_helper
    raise final_exc from source_exc
google.api_core.exceptions.RetryError: Timeout of 120.0s exceeded, last exception: 429 You exceeded your current quota, please check your plan and billing details. For more information on this error, head to: https://ai.google.dev/gemini-api/docs/rate-limits. [violations {
}
, links {
  description: "Learn more about Gemini API quotas"
  url: "https://ai.google.dev/gemini-api/docs/rate-limits"
}
, retry_delay {
  seconds: 19
}
]

