{
  "context": "Critical failure in step: investigate \u2022 coder \u2022 all training. Stopping investigation.",
  "datetime": "2025-03-30T11:03:48.998541",
  "stack_trace": "Traceback (most recent call last):\n  File \"/home/phi/PROJECTS/geometor/seer/src/geometor/seer/seer.py\", line 118, in _investigate\n        return  # Stop investigation for this task\n                    ^^^^^^^^^^^^^^^^^^^^^^^^^^^^^^\n    ...<7 lines>...\n        prompt = [\"\"]  # Minimal prompt for coder based on history\n        ^\n  File \"/home/phi/PROJECTS/geometor/seer/src/geometor/seer/seer.py\", line 306, in _generate\n    )\n    \nException: ERROR: Failed to get a valid response after 2 attempts.\n",
  "exception": "ERROR: Failed to get a valid response after 2 attempts."
}