
ERROR

IncrementalWorkflow execution failed for task f560132c
ERROR: Failed to get a valid response after 2 attempts. Last error: Response text inaccessible (finish reason: UNKNOWN)
Traceback (most recent call last):
  File "/home/phi/PROJECTS/geometor/seer/src/geometor/seer/workflows/incremental/workflow.py", line 61, in execute
    task_step = self._investigate_dreamer_step(
        session_task,
    ...<5 lines>...
        is_first_pair,
    )
  File "/home/phi/PROJECTS/geometor/seer/src/geometor/seer/workflows/incremental/workflow.py", line 176, in _investigate_dreamer_step
    task_step = seer_instance._generate(
        session_task,
    ...<5 lines>...
        tools="code_execution", # Dreamer might still use tools
    )
  File "/home/phi/PROJECTS/geometor/seer/src/geometor/seer/seer.py", line 348, in _generate
    raise exc # Raise the exception to be caught by the caller
    ^^^^^^^^^
Exception: ERROR: Failed to get a valid response after 2 attempts. Last error: Response text inaccessible (finish reason: UNKNOWN)

