{
  "context": "DefaultWorkflow execution failed for task a8610ef7",
  "datetime": "2025-04-11T10:54:02.483205",
  "stack_trace": "Traceback (most recent call last):\n  File \"/home/phi/PROJECTS/geometor/seer/src/geometor/seer/workflows/default/workflow.py\", line 81, in execute\n    task_step = self._refine_iteration(\n        session_task,\n    ...<4 lines>...\n        current_iteration,\n    )\n  File \"/home/phi/PROJECTS/geometor/seer/src/geometor/seer/workflows/default/workflow.py\", line 221, in _refine_iteration\n    task_step = seer_instance._generate(\n        session_task,\n    ...<5 lines>...\n        tools=\"code_execution\",\n    )\n  File \"/home/phi/PROJECTS/geometor/seer/src/geometor/seer/seer.py\", line 349, in _generate\n    raise exc # Raise the exception to be caught by the caller\n    ^^^^^^^^^\nException: ERROR: Failed to get a valid response after 2 attempts. Last error: Response text inaccessible (finish reason: UNKNOWN)\n",
  "exception": "ERROR: Failed to get a valid response after 2 attempts. Last error: Response text inaccessible (finish reason: UNKNOWN)"
}