{
  "context": "Critical failure in step: refine \u2022 1 \u2022 coder during refinement iteration 1.",
  "datetime": "2025-04-03T00:05:28.599745",
  "stack_trace": "Traceback (most recent call last):\n  File \"/home/phi/PROJECTS/geometor/seer/src/geometor/seer/seer.py\", line 386, in refine\n    if task_step.attempts > 0:\n                ^^^^^^^^^^^^^^\n    ...<7 lines>...\n    \n    \n  File \"/home/phi/PROJECTS/geometor/seer/src/geometor/seer/seer.py\", line 304, in _generate\n    elif isinstance(predicted_grid_obj.grid, list):\n    \nException: ERROR: Failed to get a valid response after 2 retries.\n",
  "exception": "ERROR: Failed to get a valid response after 2 retries."
}