{
  "context": "Unable to get valid response. Stopping investigation.",
  "datetime": "2025-04-02T11:41:44.885105",
  "stack_trace": "Traceback (most recent call last):\n  File \"/home/phi/PROJECTS/geometor/seer/src/geometor/seer/seer.py\", line 122, in _investigate\n    task_step = self._generate(\n        session_task,\n    ...<5 lines>...\n        tools=\"code_execution\",\n    )\n  File \"/home/phi/PROJECTS/geometor/seer/src/geometor/seer/seer.py\", line 288, in _generate\n    task_step = session_task.add_step(title, history, content, instructions, client.model_name)\nTypeError: SessionTask.add_step() takes 5 positional arguments but 6 were given\n",
  "exception": "SessionTask.add_step() takes 5 positional arguments but 6 were given"
}