{
  "context": "DefaultWorkflow execution failed for task e8686506",
  "datetime": "2025-04-10T20:37:44.759166",
  "stack_trace": "Traceback (most recent call last):\n  File \"/home/phi/PROJECTS/geometor/seer/src/geometor/seer/workflows/default/workflow.py\", line 54, in execute\n    task_step = self._investigate_dreamer(\n        session_task, task, seer_instance, history\n    )\n  File \"/home/phi/PROJECTS/geometor/seer/src/geometor/seer/workflows/default/workflow.py\", line 156, in _investigate_dreamer\n    task_step = seer_instance._generate(\n        session_task,\n    ...<6 lines>...\n        tools=\"\",\n    )\n  File \"/home/phi/PROJECTS/geometor/seer/src/geometor/seer/seer.py\", line 345, in _generate\n    raise exc # Raise the exception to be caught by the caller\n    ^^^^^^^^^\nException: ERROR: Failed to get a valid response after 2 attempts. Last error: No response candidates received\n",
  "exception": "ERROR: Failed to get a valid response after 2 attempts. Last error: No response candidates received"
}