{
  "context": "Critical failure in step: refine \u2022 0 \u2022 dreamer during refinement iteration 0.",
  "datetime": "2025-03-30T09:51:35.232137",
  "stack_trace": "Traceback (most recent call last):\n  File \"/home/phi/PROJECTS/geometor/seer/src/geometor/seer/seer.py\", line 350, in refine\n    task_step = self._generate(\n        session_task,\n    ...<5 lines>...\n        tools=\"code_execution\",\n    )\n  File \"/home/phi/PROJECTS/geometor/seer/src/geometor/seer/seer.py\", line 306, in _generate\n    raise exc # Raise the exception to be caught by the caller (_investigate or refine)\n    ^^^^^^^^^\nException: ERROR: Failed to get a valid response after 2 attempts.\n",
  "exception": "ERROR: Failed to get a valid response after 2 attempts."
}