
ERROR

Critical failure in step: investigate • dreamer • all training. Stopping investigation.
ERROR: Failed to get a valid response after 2 attempts.
Traceback (most recent call last):
  File "/home/phi/PROJECTS/geometor/seer/src/geometor/seer/seer.py", line 83, in _investigate
        "dreamer",
                ^^
    ...<7 lines>...
    history.extend(prompt)
    ^
  File "/home/phi/PROJECTS/geometor/seer/src/geometor/seer/seer.py", line 306, in _generate
    # --- If we reach here, it means loop broke successfully with a valid response ---
Exception: ERROR: Failed to get a valid response after 2 attempts.

