{
  "context": "Critical failure in step: refine \u2022 0 \u2022 coder during refinement iteration 0.",
  "datetime": "2025-04-01T13:34:25.145998",
  "stack_trace": "Traceback (most recent call last):\n  File \"/home/phi/PROJECTS/geometor/seer/src/geometor/seer/seer.py\", line 386, in refine\n    task_step = self._generate(\n        session_task,\n    ...<5 lines>...\n        #  tools=\"code_execution\" # Coder might not need tools\n    )\n  File \"/home/phi/PROJECTS/geometor/seer/src/geometor/seer/seer.py\", line 304, in _generate\n    raise exc # Raise the exception to be caught by the caller (_investigate or refine)\n    ^^^^^^^^^\nException: ERROR: Failed to get a valid response after 2 retries.\n",
  "exception": "ERROR: Failed to get a valid response after 2 retries."
}