
ERROR

Critical failure during refinement iteration 1. Stopping investigation.
ERROR: Failed to get a valid response after 2 attempts.
Traceback (most recent call last):
  File "/home/phi/PROJECTS/geometor/seer/src/geometor/seer/seer.py", line 165, in _investigate
        session_task.log_error(
                    ^^^^^^^^^^^
    ...<6 lines>...
        # Handle the case where there's no code trial (e.g., coder failed to produce code)
        ^
  File "/home/phi/PROJECTS/geometor/seer/src/geometor/seer/seer.py", line 418, in refine
    task_step.run_trials()
    ^^^^^^^
  File "/home/phi/PROJECTS/geometor/seer/src/geometor/seer/seer.py", line 391, in refine
    task_step = None  # Initialize task_step
                    ^^^^^^^^^^^^^^^^^^^^^^^^
    ...<7 lines>...
        instructions = [self.instructions["refine_dreamer"]]
        ^
  File "/home/phi/PROJECTS/geometor/seer/src/geometor/seer/seer.py", line 306, in _generate
    )
    
Exception: ERROR: Failed to get a valid response after 2 attempts.

