{
  "context": "Unable to get valid reponse. Stopping investigation.",
  "datetime": "2025-04-02T16:19:26.113045",
  "stack_trace": "Traceback (most recent call last):\n  File \"/home/phi/PROJECTS/geometor/seer/src/geometor/seer/seer.py\", line 130, in _investigate\n    )\n  File \"/home/phi/PROJECTS/geometor/seer/src/geometor/seer/session/task_step.py\", line 416, in run_trials\n    pass\n  File \"/home/phi/PROJECTS/geometor/seer/src/geometor/seer/trials/step_code_trials.py\", line 26, in run_trials\n    code_trial = CodeTrial(self.task_step, code_filename, code, task)\n  File \"/home/phi/PROJECTS/geometor/seer/src/geometor/seer/trials/code_trial.py\", line 76, in __init__\n        self.average_score = self.total_score / len(valid_scores)\n                    ^^^^^^^^^^^^^^^^^^^^^^^^^^^^^^^^^^^^^^^^^^^^^\n    ...<3 lines>...\n         # Let's keep it None to indicate no comparable results.\n    \n  File \"/home/phi/PROJECTS/geometor/seer/src/geometor/seer/tasks/tasks.py\", line 164, in to_image\n    result_row.append(result.transformed_output.to_image(add_text=False))\n       ^^^^^^^^^^^^^^^^^^^^^^^^^^^^^^^^^^^^^^^^^^^\n  File \"/home/phi/PROJECTS/geometor/seer/src/geometor/seer/tasks/tasks.py\", line 159, in get_table_images\n    if result_set and \"trials\" in result_set:\n                              ^^^^^^^^^^^^^^^\n  File \"/home/phi/PROJECTS/geometor/seer/src/geometor/seer/tasks/grid.py\", line 252, in to_image\n    width = grid.width * cell_size\n            ^^^^^^^^^^\n  File \"/home/phi/PROJECTS/geometor/seer/src/geometor/seer/tasks/grid.py\", line 79, in width\n    return self.grid.shape[1]\n           ~~~~~~~~~~~~~~~^^^\nIndexError: tuple index out of range\n",
  "exception": "tuple index out of range"
}