
ERROR

Critical failure in step: investigate • dreamer • all training. Stopping investigation.
ERROR: Failed to get a valid response after 2 attempts.
Traceback (most recent call last):
  File "/home/phi/PROJECTS/geometor/seer/src/geometor/seer/seer.py", line 81, in _investigate
    task_step = self._generate(
        session_task,
    ...<5 lines>...
        tools="code_execution",
    )
  File "/home/phi/PROJECTS/geometor/seer/src/geometor/seer/seer.py", line 300, in _generate
    task_step.log_error(exc, "Final Generate Failure after all retries")
    ^^^^^^^^^
Exception: ERROR: Failed to get a valid response after 2 attempts.

