{
  "context": "",
  "datetime": "2025-03-24T17:51:46.452270",
  "stack_trace": "Traceback (most recent call last):\n  File \"/home/phi/PROJECTS/geometor/seer/src/geometor/seer/seer.py\", line 54, in solve\n    self._investigate(task, session_task)\n  File \"/home/phi/PROJECTS/geometor/seer/src/geometor/seer/seer.py\", line 137, in _investigate\n    task_step = self.refine(\n  File \"/home/phi/PROJECTS/geometor/seer/src/geometor/seer/seer.py\", line 245, in refine\n    task_step.run_trials()\n  File \"/home/phi/PROJECTS/geometor/seer/src/geometor/seer/session/task_step.py\", line 267, in run_trials\n    self.step_code_trials.run_trials()\n  File \"/home/phi/PROJECTS/geometor/seer/src/geometor/seer/trials/step_code_trials.py\", line 26, in run_trials\n    code_trial = CodeTrial(self.task_step, code_filename, code, task)\n  File \"/home/phi/PROJECTS/geometor/seer/src/geometor/seer/trials/code_trial.py\", line 76, in __init__\n    results_image = self.task.to_image(\n  File \"/home/phi/PROJECTS/geometor/seer/src/geometor/seer/tasks/tasks.py\", line 164, in to_image\n    train_images = get_table_images(self.train, train_results)\n  File \"/home/phi/PROJECTS/geometor/seer/src/geometor/seer/tasks/tasks.py\", line 159, in get_table_images\n    result_row.append(result.transformed_output.to_image(add_text=False))\n  File \"/home/phi/PROJECTS/geometor/seer/src/geometor/seer/tasks/grid.py\", line 252, in to_image\n    width = grid.width * cell_size\n  File \"/home/phi/PROJECTS/geometor/seer/src/geometor/seer/tasks/grid.py\", line 79, in width\n    return self.grid.shape[1]\nIndexError: tuple index out of range\n",
  "exception": "tuple index out of range"
}