{
  "context": "Critical failure in step: investigate \u2022 coder \u2022 all training. Stopping investigation.",
  "datetime": "2025-03-31T12:28:42.966512",
  "stack_trace": "Traceback (most recent call last):\n  File \"/home/phi/PROJECTS/geometor/seer/src/geometor/seer/seer.py\", line 118, in _investigate\n        session_task,\n                ^^^^^\n    ...<7 lines>...\n    # History update is tricky here, coder prompt is minimal, response is key\n    ^\n  File \"/home/phi/PROJECTS/geometor/seer/src/geometor/seer/seer.py\", line 306, in _generate\n    # --- If we reach here, it means loop broke successfully with a valid response ---\nException: ERROR: Failed to get a valid response after 2 attempts.\n",
  "exception": "ERROR: Failed to get a valid response after 2 attempts."
}