{
  "context": "Unable to get valid reponse. Stopping investigation.",
  "datetime": "2025-04-02T11:47:26.905138",
  "stack_trace": "Traceback (most recent call last):\n  File \"/home/phi/PROJECTS/geometor/seer/src/geometor/seer/seer.py\", line 176, in _investigate\n    task_step.run_trials()\n    ~~~~~~~~~~~~~~~~~~~~^^\n  File \"/home/phi/PROJECTS/geometor/seer/src/geometor/seer/session/task_step.py\", line 420, in run_trials\n    self.step_code_trials.run_trials()\n    ~~~~~~~~~~~~~~~~~~~~~~~~~~~~~~~~^^\n  File \"/home/phi/PROJECTS/geometor/seer/src/geometor/seer/trials/step_code_trials.py\", line 26, in run_trials\n    code_trial = CodeTrial(self.task_step, code_filename, code, task)\n  File \"/home/phi/PROJECTS/geometor/seer/src/geometor/seer/trials/code_trial.py\", line 88, in __init__\n    results_image = self.task.to_image(\n        train_results=self.train_results,\n        test_results=self.test_results,\n        show_test=show_test,\n    )\n  File \"/home/phi/PROJECTS/geometor/seer/src/geometor/seer/tasks/tasks.py\", line 169, in to_image\n    train_images = get_table_images(self.train, train_results)\n  File \"/home/phi/PROJECTS/geometor/seer/src/geometor/seer/tasks/tasks.py\", line 164, in get_table_images\n    result_row.append(result.transformed_output.to_image(add_text=False))\n                      ^^^^^^^^^^^^^^^^^^^^^^^^^^^^^^^^^^\nAttributeError: 'NoneType' object has no attribute 'to_image'\n",
  "exception": "'NoneType' object has no attribute 'to_image'"
}