{
  "context": "",
  "datetime": "2025-03-20T06:54:05.680164",
  "stack_trace": "Traceback (most recent call last):\n  File \"/home/phi/PROJECTS/geometor/seer/src/geometor/seer/seer.py\", line 58, in solve\n    self._investigate(task, session_task)\n    ~~~~~~~~~~~~~~~~~^^^^^^^^^^^^^^^^^^^^\n  File \"/home/phi/PROJECTS/geometor/seer/src/geometor/seer/seer.py\", line 121, in _investigate\n    task_results = task_step.run_trials(task)\n  File \"/home/phi/PROJECTS/geometor/seer/src/geometor/seer/session/task_step.py\", line 270, in run_trials\n    r.get(\"match\", False) for r in self.train_results.get(\"trials\", [])\n                                   ^^^^^^^^^^^^^^^^^^\nAttributeError: 'TaskStep' object has no attribute 'train_results'\n",
  "exception": "'TaskStep' object has no attribute 'train_results'"
}