{
  "context": "Unable to get valid response. Stopping investigation.",
  "datetime": "2025-04-02T11:46:19.255186",
  "stack_trace": "Traceback (most recent call last):\n  File \"/home/phi/PROJECTS/geometor/seer/src/geometor/seer/seer.py\", line 165, in _investigate\n        \"coder\",\n    \n    ...<6 lines>...\n    # History update is tricky here, coder prompt is minimal, response is key\n    ^^^^^\n  File \"/home/phi/PROJECTS/geometor/seer/src/geometor/seer/seer.py\", line 375, in refine\n    session_task: SessionTask,\n        ^^^^^^^\n  File \"/home/phi/PROJECTS/geometor/seer/src/geometor/seer/seer.py\", line 345, in refine\n    \n    \n    ...<7 lines>...\n        print(f\"            {error_msg}\")\n        ^^^^^^^^^\n  File \"/home/phi/PROJECTS/geometor/seer/src/geometor/seer/seer.py\", line 304, in _generate\n    if task_step.attempts > 0:\n    ^^^^^^^^^\nException: ERROR: Failed to get a valid response after 2 retries.\n",
  "exception": "ERROR: Failed to get a valid response after 2 retries."
}