
ERROR

DefaultWorkflow execution failed for task 16de56c4
ERROR: Failed to get a valid response after 2 attempts. Last error: Response text inaccessible (finish reason: UNKNOWN)
Traceback (most recent call last):
  File "/home/phi/PROJECTS/geometor/seer/src/geometor/seer/workflows/default/workflow.py", line 54, in execute
    task_step = self._investigate_dreamer(
        session_task, task, seer_instance, history
    )
  File "/home/phi/PROJECTS/geometor/seer/src/geometor/seer/workflows/default/workflow.py", line 156, in _investigate_dreamer
    task_step = seer_instance._generate(
        session_task,
    ...<5 lines>...
        tools="code_execution",
    )
  File "/home/phi/PROJECTS/geometor/seer/src/geometor/seer/seer.py", line 345, in _generate
    raise exc # Raise the exception to be caught by the caller
    ^^^^^^^^^
Exception: ERROR: Failed to get a valid response after 2 attempts. Last error: Response text inaccessible (finish reason: UNKNOWN)

