{
  "context": "Error during summarization of TaskStep: refine \u2022 0 \u2022 coder",
  "datetime": "2025-03-26T20:08:46.168683",
  "stack_trace": "Traceback (most recent call last):\n  File \"/home/phi/PROJECTS/geometor/seer/src/geometor/seer/session/task_step.py\", line 85, in summarize\n    # Retrieve retries count, default to None if not logged\nAttributeError: 'GenerateContentResponse' object has no attribute 'get'\n",
  "exception": "'GenerateContentResponse' object has no attribute 'get'"
}