
ERROR


'TaskStep' object has no attribute 'log_warning'
Traceback (most recent call last):
  File "/home/phi/PROJECTS/geometor/seer/src/geometor/seer/seer.py", line 55, in solve
    self._investigate(task, session_task)
    ~~~~~~~~~~~~~~~~~^^^^^^^^^^^^^^^^^^^^
  File "/home/phi/PROJECTS/geometor/seer/src/geometor/seer/seer.py", line 79, in _investigate
    task_step = self._generate(
        session_task,
    ...<5 lines>...
        tools="code_execution",
    )
  File "/home/phi/PROJECTS/geometor/seer/src/geometor/seer/seer.py", line 233, in _generate
    reponse_parts = task_step.process_response(response)
  File "/home/phi/PROJECTS/geometor/seer/src/geometor/seer/session/task_step.py", line 246, in process_response
    if response.prompt_feedback.safety_ratings:
     ^^^^^^^^^^^^^^^^
AttributeError: 'TaskStep' object has no attribute 'log_warning'

