
ERROR

Critical failure during refinement iteration 1. Stopping investigation.
ERROR: Failed to get a valid response after 2 attempts.
Traceback (most recent call last):
  File "/home/phi/PROJECTS/geometor/seer/src/geometor/seer/seer.py", line 165, in _investigate
        session_task.log_error(
                    ^^^^^^^^^^^
    ...<6 lines>...
        # Handle the case where there's no code trial (e.g., coder failed to produce code)
        ^
  File "/home/phi/PROJECTS/geometor/seer/src/geometor/seer/seer.py", line 380, in refine
    history: list,  # Accept history from caller (_investigate)
        ^^^^^^^
  File "/home/phi/PROJECTS/geometor/seer/src/geometor/seer/seer.py", line 350, in refine
    # Log the final response received (even if invalid or None) before raising
            ^^^^^^^^^^^^^^^^^^^^^^^^^^^^^^^^^^^^^^^^^^^^^^^^^^^^^^^^^^^^^^^^^^
    ...<7 lines>...
    task_step.log_error(exc, "Final Generate Failure after all retries")
    
  File "/home/phi/PROJECTS/geometor/seer/src/geometor/seer/seer.py", line 306, in _generate
    )
    
Exception: ERROR: Failed to get a valid response after 2 attempts.

