{
  "context": "Unable to get valid response. Stopping investigation.",
  "datetime": "2025-04-01T21:47:10.575763",
  "stack_trace": "Traceback (most recent call last):\n  File \"/home/phi/PROJECTS/geometor/seer/src/geometor/seer/seer.py\", line 165, in _investigate\n    task_step = self.refine(\n        session_task,\n    ...<4 lines>...\n        history, # Pass current history state\n    )\n  File \"/home/phi/PROJECTS/geometor/seer/src/geometor/seer/seer.py\", line 413, in refine\n    raise e # Re-raise the exception\n    ^^^^^^^\n  File \"/home/phi/PROJECTS/geometor/seer/src/geometor/seer/seer.py\", line 401, in refine\n    task_step.run_trials()\n    ~~~~~~~~~~~~~~~~~~~~^^\n  File \"/home/phi/PROJECTS/geometor/seer/src/geometor/seer/session/task_step.py\", line 416, in run_trials\n    self.step_code_trials.run_trials()\n    ~~~~~~~~~~~~~~~~~~~~~~~~~~~~~~~~^^\n  File \"/home/phi/PROJECTS/geometor/seer/src/geometor/seer/trials/step_code_trials.py\", line 26, in run_trials\n    code_trial = CodeTrial(self.task_step, code_filename, code, task)\n  File \"/home/phi/PROJECTS/geometor/seer/src/geometor/seer/trials/code_trial.py\", line 76, in __init__\n    results_image = self.task.to_image(\n        train_results=self.train_results,\n        test_results=self.test_results,\n        show_test=show_test,\n    )\n  File \"/home/phi/PROJECTS/geometor/seer/src/geometor/seer/tasks/tasks.py\", line 164, in to_image\n    train_images = get_table_images(self.train, train_results)\n  File \"/home/phi/PROJECTS/geometor/seer/src/geometor/seer/tasks/tasks.py\", line 159, in get_table_images\n    result_row.append(result.transformed_output.to_image(add_text=False))\n                      ~~~~~~~~~~~~~~~~~~~~~~~~~~~~~~~~~~^^^^^^^^^^^^^^^^\n  File \"/home/phi/PROJECTS/geometor/seer/src/geometor/seer/tasks/grid.py\", line 266, in to_image\n    color = COLOR_MAP.get(grid.grid[y, x], (0, 0, 0))\nTypeError: unhashable type: 'numpy.ndarray'\n",
  "exception": "unhashable type: 'numpy.ndarray'"
}