{
  "context": "Critical failure in step: refine \u2022 0 \u2022 dreamer during refinement iteration 0.",
  "datetime": "2025-04-02T23:03:33.593910",
  "stack_trace": "Traceback (most recent call last):\n  File \"/home/phi/PROJECTS/geometor/seer/src/geometor/seer/seer.py\", line 345, in refine\n    \n    \n    ...<7 lines>...\n        instructions: List[str], # Specific instructions for this turn\n        ^^^^^^^^^\n  File \"/home/phi/PROJECTS/geometor/seer/src/geometor/seer/seer.py\", line 304, in _generate\n    elif isinstance(predicted_grid_obj.grid, list):\n    \nException: ERROR: Failed to get a valid response after 2 retries.\n",
  "exception": "ERROR: Failed to get a valid response after 2 retries."
}